<mujoco model="skateboard">
  <default>
    <default class="skateboard">
      <default class="truck">
        <geom type="capsule" size="0.03" rgba="0.4414 0.4727 0.4922 1"/>
      </default>
      <default class="hanger">
        <!-- TODO(hartikainen): need to fix the orientation for the bodies previously -->
        <!-- welded by these fixed joints. -->
        <!-- <joint type="fixed" pos="0.0 0.0 0.0" axis="0 1 0" range="-45 45"/> -->
        <geom type="capsule" fromto="0.0 0.1 -0.05 0.0 -0.1 -0.05" size="0.015" rgba="0.4414 0.4727 0.4922 1"/>
      </default>
      <default class="wheel">
        <!-- TODO(hartikainen): need to fix the orientation for the bodies previously -->
        <!-- welded by these fixed joints. -->
        <!-- <joint type="fixed" pos="0.0 0.0 0.0" axis="0 1 0" range="-45 45"/> -->
        <geom type="sphere" size="0.03" rgba="0.8867 0.2383 0.5781 1"/>
      </default>
    </default>
  </default>

  <worldbody>
    <!-- for tweaking Skateboard.xml alone in MuJoCo <geom name="floor_2" type="plane" conaffinity="1" size="50 50 .05"/> -->
    <!-- <geom name="floor_2" type="plane" conaffinity="1" size="50 50 .05"/> -->
    <geom name="floor" type="plane" conaffinity="1" size="50 50 .05" material="blue_grid"/>
    <camera name="lookat" mode="targetbodycom" target="pendulum_center" pos="0 -2 3"/>
    <body name="skateboard" pos="0 0 0.2">
      <freejoint/>
      <!-- board -->
      <body name="board">
        <body name="board_center">
          <geom name="board-base" type="box" size="0.3 0.13 0.01" rgba="0.5859 0.4336 0.1992 1"/>
        </body>
        <geom name="board-nose" type="box" size="0.075 0.13 0.01" pos="0.35 0.0 0.01" quat="-0.9659 0 0.1588 0" rgba="0.5859 0.4336 0.1992 1"/>
        <geom name="board-tail" type="box" size="0.075 0.13 0.01" pos="-0.35 0.0 0.01" quat="0.9659 0 0.1588 0" rgba="0.5859 0.4336 0.1992 1"/>
      </body>
      <!-- trucks -->
      <geom name="truck-nose" class="truck" fromto="0.20 0.0 -0.020 0.30 0.0 -0.020"/>
      <geom name="truck-tail" class="truck" fromto="-0.20 0.0 -0.020 -0.30 0.0 -0.020"/>

       <!-- Baseplate -->
      <body name="baseplate-front" pos="0.25 0.0 -0.01">
        <geom type="box" size="0.05 0.1 0.01" rgba="0.5 0.5 0.5 1"/>
        <body name="kingpin-front" pos="0 0 -0.01">
          <geom type="capsule" fromto="0 0 0 0 0 -0.05" size="0.01" rgba="0.5 0.5 0.5 1"/>

          <!-- Bushings and hanger -->
          <body name="bushings-and-hanger-front" pos="0 0 -0.06">
            <geom name="bottom-bushing-front" type="ellipsoid" size="0.03 0.03 0.01" rgba="1 0 0 1"/>
            <geom name="hanger-front" type="box" size="0.02 0.12 0.02" pos="0 0 -0.03" rgba="0.5 0.5 0.5 1"/>

            <!-- Wheels -->
            <body name="wheel-front-left" pos="0.0 0.15 -0.02">
              <joint name="wheel-front-left" type="hinge" axis="0 1 0"/>
              <geom type="cylinder" size="0.04 0.02" rgba="0.1 0.1 0.1 1" quat="0.707 0.707 0 0"/>
            </body>
            <body name="wheel-front-right" pos="0.0 -0.15 -0.02">
              <joint name="wheel-front-right" type="hinge" axis="0 1 0"/>
              <geom type="cylinder" size="0.04 0.02" rgba="0.1 0.1 0.1 1" quat="0.707 0.707 0 0"/>
            </body>

            <!-- Hinge joint that allows the hanger to rotate -->
            <!-- <joint name="hanger-rotate" type="hinge" axis="1 0 0" range="-1 1" limited="true" damping="1" stiffness="100"/> -->
          </body>
        </body>
      </body>
      <!-- identical but for back truck -->
      <body name="baseplate-back" pos="-0.25 0.0 -0.01">
        <geom type="box" size="0.05 0.1 0.01" rgba="0.5 0.5 0.5 1"/>
        <body name="kingpin-back" pos="0 0 -0.01">
          <geom type="capsule" fromto="0 0 0 0 0 -0.05" size="0.01" rgba="0.5 0.5 0.5 1"/>

          <!-- Bushings and hanger -->
          <body name="bushings-and-hanger-back" pos="0 0 -0.06">
            <geom name="bottom-bushing-back" type="ellipsoid" size="0.03 0.03 0.01" rgba="1 0 0 1"/>
            <geom name="hanger-back" type="box" size="0.02 0.12 0.02" pos="0 0 -0.03" rgba="0.5 0.5 0.5 1"/>

            <!-- Wheels -->
            <body name="wheel-back-left" pos="0.0 0.15 -0.02">
              <joint name="wheel-back-left" type="hinge" axis="0 1 0"/>
              <geom type="cylinder" size="0.04 0.02" rgba="0.1 0.1 0.1 1" quat="0.707 0.707 0 0"/>
            </body>
            <body name="wheel-back-right" pos="0.0 -0.15 -0.02">
              <joint name="wheel-back-right" type="hinge" axis="0 1 0"/>
              <geom type="cylinder" size="0.04 0.02" rgba="0.1 0.1 0.1 1" quat="0.707 0.707 0 0"/>
            </body>

            <!-- Hinge joint that allows the hanger to rotate -->
            <!-- TODO(elias): need to update losses of numbered joints in order to work -->
            <!-- <joint name="hanger-rotate-back" type="hinge" axis="1 0 0" range="-1 1" limited="true" damping="1" stiffness="100"/> -->
          </body>
        </body>
      </body>
      <!-- exlude contact between all board parts,   trucks and kingpins and hangars -->
      <!-- <geom name="floor" type="plane" conaffinity="1" size="50 50 .05" material="blue_grid"/>
      <camera name="lookat" mode="targetbodycom" target="pendulum_center" pos="0 -2 3"/> -->
      <!-- <geom name="floor_2" type="plane" conaffinity="1" size="50 50 .05"/> -->


      <body name="pendulum_root" pos="0 0 0.1">
        <!-- <freejoint name="root"/> -->
        <body name="pendulum_center">
          <geom name="pendulum_root_geom" pos="0 0 0" size="0.25 0.25 0.01" type="box" rgba="0 0 1 1"/>
        </body>
        <!-- horizontal capsule below the front_capsule for tipping -->
        <body name="horizontal_capsule">
          <joint name="horizontal_capsule" type="hinge" axis="0 1 0" range="-45 45" limited="true"/>
          <geom name="horizontal_geom_capsule" fromto="0 -0.25 0.2 0 0.25 0.2" size="0.05" type="capsule" rgba="1 0 0 1"/>
          <body name="front_capsule">
            <joint name="front_capsule" type="hinge" axis="1 0 0" range="-45 45" limited="true"/>
            <geom name="front_geom_capsule" fromto="0 0 0.3 0 0 1" size="0.05" type="capsule" rgba="1 0 0 1"/>
            <!-- add heavy cube on top -->
            <body name="cube">
              <geom name="cube_geom" pos="0 0   1" size="0.125 0.125 0.125" type="box" rgba="0 1 0 1"/>
            </body>
          </body>
        </body>
      </body>  
    </body>
    
  </worldbody>
  <contact>
        <exclude body1="board" body2="baseplate-front"/>
        <exclude body1="board" body2="baseplate-back"/>
        <exclude body1="board" body2="wheel-front-left"/>
        <exclude body1="board" body2="wheel-front-right"/>
        <exclude body1="board" body2="wheel-back-left"/>
        <exclude body1="board" body2="wheel-back-right"/>
        <exclude body1="baseplate-front" body2="wheel-front-left"/>
        <exclude body1="baseplate-front" body2="wheel-front-right"/>
        <exclude body1="baseplate-front" body2="wheel-back-left"/>
        <exclude body1="baseplate-front" body2="wheel-back-right"/>
        <exclude body1="baseplate-back" body2="wheel-front-left"/>
        <exclude body1="baseplate-back" body2="wheel-front-right"/>
        <exclude body1="baseplate-back" body2="wheel-back-left"/>
        <exclude body1="baseplate-back" body2="wheel-back-right"/>
        <exclude body1="wheel-front-left" body2="wheel-front-right"/>
        <exclude body1="wheel-front-left" body2="wheel-back-left"/>
        <exclude body1="wheel-front-left" body2="wheel-back-right"/>
        <exclude body1="wheel-front-right" body2="wheel-back-left"/>
        <exclude body1="wheel-front-right" body2="wheel-back-right"/>
        <exclude body1="wheel-back-left" body2="wheel-back-right"/>
        <exclude body1="baseplate-front" body2="baseplate-back"/>
        <exclude body1="baseplate-front" body2="kingpin-front"/>
        <exclude body1="baseplate-front" body2="kingpin-back"/>
        <exclude body1="baseplate-front" body2="bushings-and-hanger-front"/>
        <exclude body1="baseplate-front" body2="bushings-and-hanger-back"/>
        <exclude body1="baseplate-back" body2="kingpin-front"/>
        <exclude body1="baseplate-back" body2="kingpin-back"/>
        <exclude body1="baseplate-back" body2="bushings-and-hanger-front"/>
        <exclude body1="baseplate-back" body2="bushings-and-hanger-back"/>
        <exclude body1="kingpin-front" body2="kingpin-back"/>
        <exclude body1="kingpin-front" body2="bushings-and-hanger-front"/>
        <exclude body1="kingpin-front" body2="bushings-and-hanger-back"/>
        <exclude body1="kingpin-back" body2="bushings-and-hanger-front"/>
        <exclude body1="kingpin-back" body2="bushings-and-hanger-back"/>
        <exclude body1="bushings-and-hanger-front" body2="bushings-and-hanger-back"/>

      </contact>  
</mujoco>
